Workbook

Sheet INSTRUCCIONES PARA IA
A1: INSTRUCCIONES PARA IA — manual operativo completo del sistema
A2: Si eres una IA que recibe este archivo: lee esta hoja entera antes de responder. Estas reglas mandan sobre cualquier memoria de conversación.
A4: § | B4: Tema | C4: Regla / procedimiento
A5: 1 | B5: ROL | C5: Eres el entrenador del usuario, especializado en el método Bilbo, fuerza y potencia, y gestor de este Excel (entrenador + base de datos + historial).
C6: Ciclo de trabajo: prescribir → recibir resultado → registrar → analizar → actualizar → progresar → prescribir de nuevo.
C7: Idioma: español. Estilo: directo, concreto, sin paja, sin explicaciones innecesarias, sin contradecir reglas ya establecidas, sin pedir datos que ya están en el Excel.
A8: 2 | B8: OBJETIVOS (en orden) | C8: 1) Maximizar fuerza. 2) Maximizar potencia. 3) Progresar de forma objetiva y medible. 4) Controlar la fatiga. 5) Mantener volumen suficiente. 6) Usar Bilbo correctamente en sus ejercicios. 7) Progresiones basadas en evidencia para el resto. 8) Registrar todos los datos relevantes. 9) Usar los datos históricos para decidir las cargas. 10) Poder continuar en cualquier momento (otra conversación u otra IA) usando el Excel como fuente de verdad.
C9: No inventar datos que no estén registrados. Nunca.
A10: 3 | B10: FUENTE DE VERDAD | C10: El Excel es la fuente de verdad. La conversación NO es el registro definitivo.
C11: Si hay discrepancia entre lo que recuerda la IA y el Excel, manda el Excel, salvo que el usuario diga expresamente que quiere modificar el sistema.
C12: Todo dato nuevo debe quedar escrito en el Excel; nunca solo en la conversación. Tras actualizar, entregar al usuario el archivo actualizado.
A13: 4 | B13: ESTRUCTURA SEMANAL (fija) | C13: LUNES — EMPUJE: 1 Press banca (Bilbo) · 2 Press militar (Bilbo) · 3 Press inclinado con mancuernas · 4 Tríceps en polea alta · 5 Elevaciones laterales.
C14: MARTES — TIRÓN + PIERNA: 1 Remo bajo en polea (Bilbo) · 2 Sentadilla · 3 Jalón al pecho O trabajo unilateral con mancuerna · 4 Bíceps con mancuernas.
C15: MIÉRCOLES — MOVILIDAD + POTENCIA: 1 Movilidad (15–20 min) · 2 Potencia: Salto vertical con contramovimiento (CMJ) 4×3, Press banca dinámico 5×3, Sentadilla dinámica 5×2. Poca fatiga, alta velocidad, técnica.
C16: JUEVES — EMPUJE: 1 Press banca (Bilbo) · 2 Press militar (Bilbo) · 3 Press inclinado con mancuernas · 4 Tríceps en polea alta · 5 Trapecio.
C17: VIERNES — TIRÓN + PIERNA: igual que el martes.
C18: El detalle (series, reps, RIR, descansos) está en la hoja PLAN SEMANAL. PROHIBIDO: peso muerto, ejercicios raros, circuitos, superseries innecesarias, acondicionamiento que interfiera, accesorios no solicitados.
A19: 5 | B19: EJERCICIOS BILBO | C19: Bilbo se aplica EXCLUSIVAMENTE a: Press banca, Press militar, Remo bajo en polea.
C20: NO Bilbo: sentadilla, bíceps, tríceps, press inclinado, elevaciones laterales, trapecio, jalón, trabajo unilateral, potencia.
A21: 6 | B21: MÉTODO BILBO EN ESTE SISTEMA | C21: Una serie protagonista de repeticiones relativamente altas (≈15–50) con intención explosiva en cada repetición, sin llegar al fallo absoluto.
C22: Carga moderada al inicio del ciclo. La carga sube en CADA sesión (+1 incremento mínimo del ejercicio, p. ej. +2 kg). Las repeticiones bajan progresivamente.
C23: El ciclo termina por RENDIMIENTO, no por calendario: cuando la serie Bilbo queda en ≈15 reps (CONFIGURACIÓN 'Bilbo: reps de fin de ciclo'). No hay duración fija (no 6 semanas).
C24: NO convertir Bilbo en 3×5, 3×6, etc. NO mantener el mismo peso hasta superar las reps anteriores. Lógica: sube carga → bajan reps → sigue subiendo → ≈15 reps fin → nuevo ciclo con carga inicial superior a la inicial anterior.
C25: Qué es específico de Bilbo y qué es evidencia general: la estructura (serie única alta en reps + subida lineal por sesión + reinicio) es propia del método; no afirmar que Bilbo sea científicamente superior a otros métodos (no hay evidencia suficiente). Sí están respaldados: sobrecarga progresiva, intención de velocidad máxima, volumen suficiente con series cercanas al fallo (post-Bilbo @RIR1), autorregulación y gestión de la fatiga.
A26: 7 | B26: REGLA CRÍTICA DE CICLOS | C26: Cuando termina un ciclo, el siguiente NUNCA empieza con una carga igual o inferior a la carga INICIAL del ciclo anterior. Debe ser SUPERIOR.
C27: Ejemplo: ciclo 1 = 60×31, 62×28, 64×25, 66×22, 68×19, 70×16 → ciclo 2 empieza p. ej. con 62 kg × ≈30.
C28: Carga inicial nueva (fórmula de sugerencia en CICLOS BILBO col. T y ESTADO ACTUAL): máx(inicial anterior + 1 incremento; inicial anterior × (1 + 'Nuevo ciclo: subida mínima %')), redondeada hacia arriba al incremento. La IA decide la cifra final con los datos reales del ciclo anterior (reps logradas con cargas cercanas): el objetivo es que el nuevo ciclo empiece con ≈ las mismas reps (o algo menos) que el anterior pero con más carga.
C29: La columna 'Regla: inicial > anterior' de CICLOS BILBO y 'Validación decisión' marcan ERROR si se viola esta regla. Nunca dejar un ERROR.
A30: 8 | B30: DECISIÓN DEL PESO BILBO DE CADA SESIÓN | C30: La IA decide el peso Bilbo; el usuario no calcula nada. Antes de cada entrenamiento indicar: peso Bilbo, reps esperadas, ciclo, posición en el ciclo y una explicación breve.
C31: Norma: próximo peso = último peso Bilbo + incremento del ejercicio (ESTADO ACTUAL col. N 'SUGERIDO'). Escribir la decisión en col. O 'DECISIÓN'.
C32: Excepciones: (a) si las últimas reps ≤ 15 → cerrar ciclo e iniciar uno nuevo (§26); (b) si las reps quedaron muy por debajo de lo estimado (≥ 'reps por debajo… rendimiento bajo', por defecto 5) → analizar (§20); una sesión mala aislada: normalmente repetir carga o subir igualmente si el contexto lo explica (sueño, horario); nunca reiniciar el ciclo por una sola sesión; (c) si el rendimiento es claramente superior a lo estimado → continuar la progresión normal (+1 incremento), sin saltos excesivos; como máximo +2 incrementos si la diferencia es muy grande y se repite.
A33: 9 | B33: ESTIMACIÓN DE REPETICIONES | C33: Modelo (ESTADO ACTUAL col. P): reps esperadas = últimas reps − (caída de reps por kg) × (próximo peso − último peso). La caída por kg se calcula con el ciclo actual ((reps iniciales − últimas reps)/(último peso − peso inicial)); si hay menos de 2 sesiones en el ciclo se usa el valor por defecto de CONFIGURACIÓN (1,5 reps/kg ≈ 3 reps por +2 kg).
C34: La IA puede corregir la estimación con su criterio (ciclos anteriores con esa carga, tendencia) en col. Q 'AJUSTE IA'; la col. R 'FINAL' es la que se comunica.
C35: La estimación no es una garantía. Registrar la estimación en HISTORIAL (col. N 'Reps estimadas') en la fila Bilbo para poder comparar después.
A36: 10 | B36: SI EL RESULTADO DIFIERE DE LO ESTIMADO | C36: Superior: no implica un salto enorme. Continuar la progresión (+1 incremento) y dejar que el modelo recoja la mejora (la estimación siguiente sube sola).
C37: Inferior: analizar magnitud, sesiones anteriores, fatiga, técnica, RIR de las series posteriores y tendencia. No reiniciar el ciclo ni bajar la carga automáticamente por una sola mala sesión. Decidir con el conjunto de datos.
A38: 11 | B38: SIN 1RM | C38: No se asume ningún 1RM ni se exigen tests máximos (solo si el usuario los pide). Las referencias se obtienen de las series reales.
C39: HISTORIAL calcula 'e1RM ref.' (Epley ajustado por RIR) solo en series de ≤12 reps y 'Índice Bilbo' (peso × (1 + reps/30)) solo para comparar tendencias entre sesiones y ciclos; ninguno es un 1RM real.
A40: 12 | B40: TRABAJO POST-BILBO | C40: En banca, militar y remo polea: 1 serie Bilbo + 3 series posteriores del mismo ejercicio. Objetivo: 3 × 8–12 @RIR 1 (cada serie termina con ≈1 rep en reserva).
C41: Peso posterior = Peso Bilbo × (1 + % añadido), redondeado al incremento según la regla de redondeo. NO reducir automáticamente el peso tras el Bilbo. Ej.: 60 × 1,15 = 69 → 70 kg (redondeo MÁS CERCANO a 2 kg).
...

Sheet CONFIGURACIÓN
A1: CONFIGURACIÓN — parámetros del sistema
A2: Parámetros modificables. Separados de los datos. Cambiar solo con autorización del usuario (registrar el cambio en INCIDENCIAS Y CAMBIOS).
A3: Leyenda: celdas AMARILLAS con texto AZUL = entrada/decisión (se editan). Celdas GRISES = fórmula (no tocar). Texto VERDE = vínculo a otra hoja (no tocar).
B5: A) PARÁMETROS GENERALES
B6: Objetivo (orden de prioridad) | C6: 1 Fuerza · 2 Potencia · 3 Progreso medible · 4 Control de fatiga · 5 Volumen suficiente · 6 Bilbo correcto · 7 Progresión basada en evidencia · 8 Registro total · 9 Decidir con historial · 10 Continuidad vía Excel | D6: Texto de referencia.
B7: Días de entrenamiento | C7: Lunes a viernes | D7: L Empuje · M Tirón+Pierna · X Movilidad+Potencia · J Empuje · V Tirón+Pierna
B8: Incremento mínimo global de carga (kg) | C8: 2 | D8: Confirmado: 2 kg (barra: 1 kg por lado; poleas: de 2 en 2 kg). Cada ejercicio tiene el suyo en la tabla B (col. H).
B9: Regla de redondeo | C9: MÁS CERCANO | D9: MÁS CERCANO / ABAJO / ARRIBA. Se aplica a todas las cargas calculadas (post-Bilbo, subidas, calentamientos usan ABAJO).
B10: Peso de la barra (kg) | C10: 10 | D10: Confirmado por el usuario (27/09/2026): barra de 10 kg. Discos de 1 kg por lado → incremento mínimo en barra 2 kg.
B11: Bilbo: reps de fin de ciclo | C11: 15 | D11: El ciclo termina cuando la serie Bilbo queda en ≈15 reps (o menos).
B12: Bilbo: reps máximas de referencia | C12: 50 | D12: Rango orientativo 15–50. Si se llega a 50 reps, parar la serie: la carga era baja.
B13: Bilbo: umbral 'ciclo próximo a terminar' (reps) | C13: 18 | D13: Si las últimas reps Bilbo ≤ este valor, el ciclo está cerca del final.
B14: Bilbo: caída de reps por kg por defecto | C14: 1.5 | D14: Se usa para estimar reps cuando aún no hay 2 sesiones en el ciclo (≈3 reps menos por +2 kg). Con datos, se calcula del ciclo real.
B15: Bilbo: caída mínima de reps por kg (suelo del modelo) | C15: 0.5 | D15: Evita estimaciones absurdas si en el ciclo las reps subieron al subir carga.
B16: Bilbo: subida de carga entre sesiones | C16: 1 incremento del ejercicio | D16: Norma: +1 incremento mínimo del ejercicio por sesión (ej. +2 kg). No mantener el peso para 'batir reps'.
B17: Nuevo ciclo: subida mínima de la carga inicial (%) | C17: 0.025 | D17: Carga inicial del nuevo ciclo ≥ carga inicial anterior + máx(1 incremento; este %). SIEMPRE superior a la inicial anterior.
B18: Bilbo: reps por debajo de lo estimado que se consideran rendimiento bajo | C18: 5 | D18: Si reps reales ≤ estimadas − este valor: no subir automáticamente; analizar fatiga (no reiniciar por una sesión).
B19: Post-Bilbo: nº de series | C19: 3 | D19: 1 serie Bilbo + 3 series posteriores del mismo ejercicio.
B20: Post-Bilbo: reps mínimas | C20: 8 | D20: Objetivo 3×8–12.
B21: Post-Bilbo: reps máximas | C21: 12
B22: Post-Bilbo: RIR objetivo | C22: 1 | D22: Cada serie termina con ≈1 repetición en reserva.
B23: Post-Bilbo: % añadido inicial | C23: 0.15 | D23: Peso post = Peso Bilbo × (1 + %). Valor inicial; después se ajusta por ejercicio en ESTADO ACTUAL.
B24: Post-Bilbo: paso de ajuste del % | C24: 0.025 | D24: Ajustes pequeños: ± este valor por sesión.
B25: Post-Bilbo: % mínimo permitido | C25: 0 | D25: Nunca se reduce el peso post por debajo del peso Bilbo salvo decisión explícita.
B26: Post-Bilbo: % máximo permitido | C26: 0.4 | D26: Tope de seguridad.
B27: Post-Bilbo: caída anormal entre S1 y S3 (reps) | C27: 4 | D27: Si S1 − S3 ≥ este valor: posible fatiga, no subir % agresivamente.
B28: Doble progresión: salto relativo mínimo al subir carga | C28: 0.025 | D28: Al completar el tope del rango: nueva carga = última + máx(incremento; % de la carga), redondeada.
B29: Tirón vertical activo (martes/viernes) | C29: Jalón al pecho | D29: Jalón al pecho / Remo unilateral con mancuerna. Cambiar cuando la pila del jalón limite la progresión.
B30: Carga máxima de la pila del jalón (kg) | C30: 60 | D30: Confirmado por el usuario: 60 kg. Si la próxima carga del jalón supera 60 kg → pasar a Remo unilateral con mancuerna (disponible).
B31: Calentamiento serie 1: % de la carga de trabajo | C31: 0.5 | D31: 2 series de aproximación. Serie 1 ≈ 50 %.
B32: Calentamiento serie 1: reps | C32: 8
B33: Calentamiento serie 2: % de la carga de trabajo | C33: 0.75 | D33: Serie 2 ≈ 75 %.
B34: Calentamiento serie 2: reps | C34: 5
B35: Potencia: carga inicial press banca dinámico (% del peso Bilbo de banca) | C35: 0.9 | D35: Solo para la primera sesión; después progresa por velocidad.
B36: Potencia: carga inicial sentadilla dinámica (% de la carga de trabajo de sentadilla) | C36: 0.65 | D36: Solo para la primera sesión; después progresa por velocidad.
B37: Movilidad articular (antes de cada sesión, 5–8 min) | C37: Cuello y hombros (círculos, dislocaciones con palo/banda) · rotaciones torácicas · círculos de cadera y 90/90 · tobillo a pared · muñecas
B38: Movilidad miércoles (15–20 min) | C38: Lo anterior más: apertura torácica en banco, sentadilla profunda asistida con pausas, estiramiento de dorsal y pectoral en polea/marco, isquios y flexores de cadera. Sin fatiga.
B40: B) EJERCICIOS, RANGOS Y PROGRESIÓN
B41: Ejercicio | C41: Tipo de progresión | D41: Implemento | E41: Rep mín | F41: Rep máx | G41: Series | H41: Incremento (kg) | I41: RIR objetivo | J41: Reps tras subir carga | K41: Día A (1=L) | L41: Día B | M41: Descanso | N41: Notas
B42: Press banca | C42: Bilbo | D42: Barra | E42: 15 | F42: 50 | G42: 1+3 | H42: 2 | I42: Bilbo: sin RIR · Post: 1 | J42: — | K42: 1 | L42: 4 | M42: Bilbo→post 3–5 min · post 2–4 min | N42: Bilbo + 3×8–12 @RIR1
...

Sheet PLAN SEMANAL
A1: PLAN SEMANAL — estructura fija (no modificar sin autorización)
A2: La columna 'Clave' la usa SESIÓN ACTUAL. El tirón vertical del martes/viernes sigue lo indicado en CONFIGURACIÓN.
A4: Clave | B4: Día | C4: Línea | D4: Sesión | E4: Ejercicio | F4: Tipo de trabajo | G4: Series | H4: Reps / rango | I4: RIR | J4: Descanso | K4: 2 series aproximación | L4: Notas
A5: =B5&"|"&C5 -> LUNES|1 | B5: LUNES | C5: 1 | D5: EMPUJE | E5: Press banca | F5: Bilbo | G5: 1 | H5: Máx. con intención explosiva (≈15–50), sin fallo absoluto | I5: No se pide | J5: 3–5 min antes de las post | K5: Sí | L5: Serie protagonista.
A6: =B6&"|"&C6 -> LUNES|2 | B6: LUNES | C6: 2 | D6: EMPUJE | E6: Press banca | F6: Post-Bilbo | G6: 3 | H6: 8–12 | I6: 1 | J6: 2–4 min | K6: No | L6: Peso = Bilbo × (1+%).
A7: =B7&"|"&C7 -> LUNES|3 | B7: LUNES | C7: 3 | D7: EMPUJE | E7: Press militar | F7: Bilbo | G7: 1 | H7: Máx. con intención explosiva (≈15–50), sin fallo absoluto | I7: No se pide | J7: 3–5 min antes de las post | K7: Sí
A8: =B8&"|"&C8 -> LUNES|4 | B8: LUNES | C8: 4 | D8: EMPUJE | E8: Press militar | F8: Post-Bilbo | G8: 3 | H8: 8–12 | I8: 1 | J8: 2–4 min | K8: No
A9: =B9&"|"&C9 -> LUNES|5 | B9: LUNES | C9: 5 | D9: EMPUJE | E9: Press inclinado con mancuernas | F9: Trabajo | G9: 3 | H9: 6–10 | I9: 1 | J9: 2–3 min | K9: No | L9: Doble progresión.
A10: =B10&"|"&C10 -> LUNES|6 | B10: LUNES | C10: 6 | D10: EMPUJE | E10: Tríceps en polea alta | F10: Trabajo | G10: 3 | H10: 3–8 | I10: 1 | J10: 2–3 min | K10: No | L10: Doble progresión.
A11: =B11&"|"&C11 -> LUNES|7 | B11: LUNES | C11: 7 | D11: EMPUJE | E11: Elevaciones laterales | F11: Trabajo | G11: 3 | H11: 10–20 | I11: 1 | J11: 1,5–2 min | K11: No | L11: Doble progresión.
A12: =B12&"|"&C12 -> MARTES|1 | B12: MARTES | C12: 1 | D12: TIRÓN + PIERNA | E12: Remo bajo en polea | F12: Bilbo | G12: 1 | H12: Máx. con intención explosiva (≈15–50), sin fallo absoluto | I12: No se pide | J12: 3–5 min antes de las post | K12: Sí
A13: =B13&"|"&C13 -> MARTES|2 | B13: MARTES | C13: 2 | D13: TIRÓN + PIERNA | E13: Remo bajo en polea | F13: Post-Bilbo | G13: 3 | H13: 8–12 | I13: 1 | J13: 2–4 min | K13: No
A14: =B14&"|"&C14 -> MARTES|3 | B14: MARTES | C14: 3 | D14: TIRÓN + PIERNA | E14: Sentadilla | F14: Trabajo | G14: 3 | H14: 3–8 | I14: 1–2 | J14: 3–4 min | K14: Sí | L14: Doble progresión. Nunca <3 ni >8.
A15: =B15&"|"&C15 -> MARTES|4 | B15: MARTES | C15: 4 | D15: TIRÓN + PIERNA | E15: =CONFIGURACIÓN!$C$29 -> Jalón al pecho | F15: Trabajo | G15: 3 | H15: 8–15 | I15: 1 | J15: 2–3 min | K15: No | L15: Jalón al pecho O remo unilateral (CONFIGURACIÓN).
A16: =B16&"|"&C16 -> MARTES|5 | B16: MARTES | C16: 5 | D16: TIRÓN + PIERNA | E16: Bíceps con mancuernas | F16: Trabajo | G16: 3 | H16: 3–8 | I16: 1 | J16: 2–3 min | K16: No | L16: Doble progresión.
A17: =B17&"|"&C17 -> MIÉRCOLES|1 | B17: MIÉRCOLES | C17: 1 | D17: MOVILIDAD + POTENCIA | E17: Movilidad | F17: Movilidad | G17: 1 | H17: 15–20 min | I17: — | J17: — | K17: No | L17: Ver CONFIGURACIÓN: movilidad miércoles.
A18: =B18&"|"&C18 -> MIÉRCOLES|2 | B18: MIÉRCOLES | C18: 2 | D18: MOVILIDAD + POTENCIA | E18: Salto vertical (CMJ) | F18: Potencia | G18: 4 | H18: 3 saltos | I18: Lejos del fallo | J18: 90–120 s | K18: No | L18: Máxima altura; reset entre saltos.
A19: =B19&"|"&C19 -> MIÉRCOLES|3 | B19: MIÉRCOLES | C19: 3 | D19: MOVILIDAD + POTENCIA | E19: Press banca dinámico | F19: Potencia | G19: 5 | H19: 3 reps a máxima velocidad | I19: ≥4 | J19: 90–120 s | K19: Sí | L19: Parar si la velocidad cae (calificar A/B/C).
A20: =B20&"|"&C20 -> MIÉRCOLES|4 | B20: MIÉRCOLES | C20: 4 | D20: MOVILIDAD + POTENCIA | E20: Sentadilla dinámica | F20: Potencia | G20: 5 | H20: 2 reps a máxima velocidad | I20: ≥5 | J20: 2 min | K20: Sí | L20: Parar si la velocidad cae (calificar A/B/C).
A21: =B21&"|"&C21 -> JUEVES|1 | B21: JUEVES | C21: 1 | D21: EMPUJE | E21: Press banca | F21: Bilbo | G21: 1 | H21: Máx. con intención explosiva (≈15–50), sin fallo absoluto | I21: No se pide | J21: 3–5 min antes de las post | K21: Sí | L21: Serie protagonista.
A22: =B22&"|"&C22 -> JUEVES|2 | B22: JUEVES | C22: 2 | D22: EMPUJE | E22: Press banca | F22: Post-Bilbo | G22: 3 | H22: 8–12 | I22: 1 | J22: 2–4 min | K22: No | L22: Peso = Bilbo × (1+%).
A23: =B23&"|"&C23 -> JUEVES|3 | B23: JUEVES | C23: 3 | D23: EMPUJE | E23: Press militar | F23: Bilbo | G23: 1 | H23: Máx. con intención explosiva (≈15–50), sin fallo absoluto | I23: No se pide | J23: 3–5 min antes de las post | K23: Sí
A24: =B24&"|"&C24 -> JUEVES|4 | B24: JUEVES | C24: 4 | D24: EMPUJE | E24: Press militar | F24: Post-Bilbo | G24: 3 | H24: 8–12 | I24: 1 | J24: 2–4 min | K24: No
A25: =B25&"|"&C25 -> JUEVES|5 | B25: JUEVES | C25: 5 | D25: EMPUJE | E25: Press inclinado con mancuernas | F25: Trabajo | G25: 3 | H25: 6–10 | I25: 1 | J25: 2–3 min | K25: No | L25: Doble progresión.
A26: =B26&"|"&C26 -> JUEVES|6 | B26: JUEVES | C26: 6 | D26: EMPUJE | E26: Tríceps en polea alta | F26: Trabajo | G26: 3 | H26: 3–8 | I26: 1 | J26: 2–3 min | K26: No | L26: Doble progresión.
A27: =B27&"|"&C27 -> JUEVES|7 | B27: JUEVES | C27: 7 | D27: EMPUJE | E27: Trapecio | F27: Trabajo | G27: 3 | H27: 8–15 | I27: 1 | J27: 1,5–2 min | K27: No | L27: Doble progresión.
A28: =B28&"|"&C28 -> VIERNES|1 | B28: VIERNES | C28: 1 | D28: TIRÓN + PIERNA | E28: Remo bajo en polea | F28: Bilbo | G28: 1 | H28: Máx. con intención explosiva (≈15–50), sin fallo absoluto | I28: No se pide | J28: 3–5 min antes de las post | K28: Sí
A29: =B29&"|"&C29 -> VIERNES|2 | B29: VIERNES | C29: 2 | D29: TIRÓN + PIERNA | E29: Remo bajo en polea | F29: Post-Bilbo | G29: 3 | H29: 8–12 | I29: 1 | J29: 2–4 min | K29: No
A30: =B30&"|"&C30 -> VIERNES|3 | B30: VIERNES | C30: 3 | D30: TIRÓN + PIERNA | E30: Sentadilla | F30: Trabajo | G30: 3 | H30: 3–8 | I30: 1–2 | J30: 3–4 min | K30: Sí | L30: Doble progresión. Nunca <3 ni >8.
A31: =B31&"|"&C31 -> VIERNES|4 | B31: VIERNES | C31: 4 | D31: TIRÓN + PIERNA | E31: =CONFIGURACIÓN!$C$29 -> Jalón al pecho | F31: Trabajo | G31: 3 | H31: 8–15 | I31: 1 | J31: 2–3 min | K31: No | L31: Jalón al pecho O remo unilateral (CONFIGURACIÓN).
A32: =B32&"|"&C32 -> VIERNES|5 | B32: VIERNES | C32: 5 | D32: TIRÓN + PIERNA | E32: Bíceps con mancuernas | F32: Trabajo | G32: 3 | H32: 3–8 | I32: 1 | J32: 2–3 min | K32: No | L32: Doble progresión.
A34: Antes de cada sesión: movilidad articular (5–8 min) + 2 series de aproximación en los ejercicios principales (columna K).
A35: Sin peso muerto. Sin accesorios nuevos, circuitos ni superseries salvo petición expresa del usuario.
A36: Bilbo solo en: Press banca, Press militar, Remo bajo en polea.

Sheet HISTORIAL
A1: HISTORIAL — registro permanente (NUNCA borrar ni sobrescribir filas)
A2: Una fila por serie. Añadir siempre en la primera fila con 'Fecha' vacía. Rellenar solo columnas amarillas; las grises son fórmulas.
A3: Ejemplo de formato (no es un dato real): 01/10/2026 | LUNES | Press banca | Bilbo | ciclo 1 | sesión 1 | serie 1 | 62 | 30 | (RIR vacío) | | reps est. 30 ... → siguientes filas: Press banca | Post-Bilbo | ciclo 1 | sesión 1 | serie 1..3 | 70 | 12/11/10 | RIR 1 | 15 %. Mancuernas: kg por mancuerna. CMJ: peso 0 = peso corporal.
A4: ID | B4: Fecha | C4: Día semana | D4: Día del plan | E4: Ejercicio | F4: Tipo de trabajo | G4: Ciclo Bilbo | H4: Sesión en ciclo | I4: Serie nº | J4: Peso (kg) | K4: Reps | L4: RIR | M4: % post-Bilbo | N4: Reps estimadas | O4: Peso prescrito (kg) | P4: Velocidad (A/B/C) | Q4: Dif. reps vs estimadas | R4: Volumen (kg×reps) | S4: e1RM ref. (≤12 reps) | T4: Índice Bilbo (comparativo) | U4: Observaciones / incidencias | V4: Próxima carga decidida (kg) | W4: Próxima sesión (fecha) | X4: Clave Bilbo (ejercicio|ciclo|sesión) | Y4: Nueva sesión (fecha distinta a la fila anterior)
A5: =IF(B5="","",ROW()-4) | C5: =IF(B5="","",CHOOSE(WEEKDAY(B5,2),"LUNES","MARTES","MIÉRCOLES","JUEVES","VIERNES","SÁBADO","DOMINGO")) | Q5: =IF(OR(K5="",N5=""),"",K5-N5) | R5: =IF(OR(J5="",K5=""),"",J5*K5) | S5: =IF(AND(ISNUMBER(J5),ISNUMBER(K5),F5<>"Calentamiento",F5<>"Bilbo"),IF(AND(K5>0,K5<=12),ROUND(J5*(1+(K5+IF(ISNUMBER(L5),L5,0))/30),1),""),"") | T5: =IF(AND(F5="Bilbo",ISNUMBER(J5),ISNUMBER(K5)),ROUND(J5*(1+K5/30),1),"") | X5: =IF(AND(F5="Bilbo",E5<>"",G5<>"",H5<>""),E5&"|"&G5&"|"&H5,"") | Y5: =IF(B5="","",IF(B5<>0,1,0))
A6: =IF(B6="","",ROW()-4) | C6: =IF(B6="","",CHOOSE(WEEKDAY(B6,2),"LUNES","MARTES","MIÉRCOLES","JUEVES","VIERNES","SÁBADO","DOMINGO")) | Q6: =IF(OR(K6="",N6=""),"",K6-N6) | R6: =IF(OR(J6="",K6=""),"",J6*K6) | S6: =IF(AND(ISNUMBER(J6),ISNUMBER(K6),F6<>"Calentamiento",F6<>"Bilbo"),IF(AND(K6>0,K6<=12),ROUND(J6*(1+(K6+IF(ISNUMBER(L6),L6,0))/30),1),""),"") | T6: =IF(AND(F6="Bilbo",ISNUMBER(J6),ISNUMBER(K6)),ROUND(J6*(1+K6/30),1),"") | X6: =IF(AND(F6="Bilbo",E6<>"",G6<>"",H6<>""),E6&"|"&G6&"|"&H6,"") | Y6: =IF(B6="","",IF(B6<>B5,1,0))
A7: =IF(B7="","",ROW()-4) | C7: =IF(B7="","",CHOOSE(WEEKDAY(B7,2),"LUNES","MARTES","MIÉRCOLES","JUEVES","VIERNES","SÁBADO","DOMINGO")) | Q7: =IF(OR(K7="",N7=""),"",K7-N7) | R7: =IF(OR(J7="",K7=""),"",J7*K7) | S7: =IF(AND(ISNUMBER(J7),ISNUMBER(K7),F7<>"Calentamiento",F7<>"Bilbo"),IF(AND(K7>0,K7<=12),ROUND(J7*(1+(K7+IF(ISNUMBER(L7),L7,0))/30),1),""),"") | T7: =IF(AND(F7="Bilbo",ISNUMBER(J7),ISNUMBER(K7)),ROUND(J7*(1+K7/30),1),"") | X7: =IF(AND(F7="Bilbo",E7<>"",G7<>"",H7<>""),E7&"|"&G7&"|"&H7,"") | Y7: =IF(B7="","",IF(B7<>B6,1,0))
A8: =IF(B8="","",ROW()-4) | C8: =IF(B8="","",CHOOSE(WEEKDAY(B8,2),"LUNES","MARTES","MIÉRCOLES","JUEVES","VIERNES","SÁBADO","DOMINGO")) | Q8: =IF(OR(K8="",N8=""),"",K8-N8) | R8: =IF(OR(J8="",K8=""),"",J8*K8) | S8: =IF(AND(ISNUMBER(J8),ISNUMBER(K8),F8<>"Calentamiento",F8<>"Bilbo"),IF(AND(K8>0,K8<=12),ROUND(J8*(1+(K8+IF(ISNUMBER(L8),L8,0))/30),1),""),"") | T8: =IF(AND(F8="Bilbo",ISNUMBER(J8),ISNUMBER(K8)),ROUND(J8*(1+K8/30),1),"") | X8: =IF(AND(F8="Bilbo",E8<>"",G8<>"",H8<>""),E8&"|"&G8&"|"&H8,"") | Y8: =IF(B8="","",IF(B8<>B7,1,0))
A9: =IF(B9="","",ROW()-4) | C9: =IF(B9="","",CHOOSE(WEEKDAY(B9,2),"LUNES","MARTES","MIÉRCOLES","JUEVES","VIERNES","SÁBADO","DOMINGO")) | Q9: =IF(OR(K9="",N9=""),"",K9-N9) | R9: =IF(OR(J9="",K9=""),"",J9*K9) | S9: =IF(AND(ISNUMBER(J9),ISNUMBER(K9),F9<>"Calentamiento",F9<>"Bilbo"),IF(AND(K9>0,K9<=12),ROUND(J9*(1+(K9+IF(ISNUMBER(L9),L9,0))/30),1),""),"") | T9: =IF(AND(F9="Bilbo",ISNUMBER(J9),ISNUMBER(K9)),ROUND(J9*(1+K9/30),1),"") | X9: =IF(AND(F9="Bilbo",E9<>"",G9<>"",H9<>""),E9&"|"&G9&"|"&H9,"") | Y9: =IF(B9="","",IF(B9<>B8,1,0))
A10: =IF(B10="","",ROW()-4) | C10: =IF(B10="","",CHOOSE(WEEKDAY(B10,2),"LUNES","MARTES","MIÉRCOLES","JUEVES","VIERNES","SÁBADO","DOMINGO")) | Q10: =IF(OR(K10="",N10=""),"",K10-N10) | R10: =IF(OR(J10="",K10=""),"",J10*K10) | S10: =IF(AND(ISNUMBER(J10),ISNUMBER(K10),F10<>"Calentamiento",F10<>"Bilbo"),IF(AND(K10>0,K10<=12),ROUND(J10*(1+(K10+IF(ISNUMBER(L10),L10,0))/30),1),""),"") | T10: =IF(AND(F10="Bilbo",ISNUMBER(J10),ISNUMBER(K10)),ROUND(J10*(1+K10/30),1),"") | X10: =IF(AND(F10="Bilbo",E10<>"",G10<>"",H10<>""),E10&"|"&G10&"|"&H10,"") | Y10: =IF(B10="","",IF(B10<>B9,1,0))
A11: =IF(B11="","",ROW()-4) | C11: =IF(B11="","",CHOOSE(WEEKDAY(B11,2),"LUNES","MARTES","MIÉRCOLES","JUEVES","VIERNES","SÁBADO","DOMINGO")) | Q11: =IF(OR(K11="",N11=""),"",K11-N11) | R11: =IF(OR(J11="",K11=""),"",J11*K11) | S11: =IF(AND(ISNUMBER(J11),ISNUMBER(K11),F11<>"Calentamiento",F11<>"Bilbo"),IF(AND(K11>0,K11<=12),ROUND(J11*(1+(K11+IF(ISNUMBER(L11),L11,0))/30),1),""),"") | T11: =IF(AND(F11="Bilbo",ISNUMBER(J11),ISNUMBER(K11)),ROUND(J11*(1+K11/30),1),"") | X11: =IF(AND(F11="Bilbo",E11<>"",G11<>"",H11<>""),E11&"|"&G11&"|"&H11,"") | Y11: =IF(B11="","",IF(B11<>B10,1,0))
A12: =IF(B12="","",ROW()-4) | C12: =IF(B12="","",CHOOSE(WEEKDAY(B12,2),"LUNES","MARTES","MIÉRCOLES","JUEVES","VIERNES","SÁBADO","DOMINGO")) | Q12: =IF(OR(K12="",N12=""),"",K12-N12) | R12: =IF(OR(J12="",K12=""),"",J12*K12) | S12: =IF(AND(ISNUMBER(J12),ISNUMBER(K12),F12<>"Calentamiento",F12<>"Bilbo"),IF(AND(K12>0,K12<=12),ROUND(J12*(1+(K12+IF(ISNUMBER(L12),L12,0))/30),1),""),"") | T12: =IF(AND(F12="Bilbo",ISNUMBER(J12),ISNUMBER(K12)),ROUND(J12*(1+K12/30),1),"") | X12: =IF(AND(F12="Bilbo",E12<>"",G12<>"",H12<>""),E12&"|"&G12&"|"&H12,"") | Y12: =IF(B12="","",IF(B12<>B11,1,0))
A13: =IF(B13="","",ROW()-4) | C13: =IF(B13="","",CHOOSE(WEEKDAY(B13,2),"LUNES","MARTES","MIÉRCOLES","JUEVES","VIERNES","SÁBADO","DOMINGO")) | Q13: =IF(OR(K13="",N13=""),"",K13-N13) | R13: =IF(OR(J13="",K13=""),"",J13*K13) | S13: =IF(AND(ISNUMBER(J13),ISNUMBER(K13),F13<>"Calentamiento",F13<>"Bilbo"),IF(AND(K13>0,K13<=12),ROUND(J13*(1+(K13+IF(ISNUMBER(L13),L13,0))/30),1),""),"") | T13: =IF(AND(F13="Bilbo",ISNUMBER(J13),ISNUMBER(K13)),ROUND(J13*(1+K13/30),1),"") | X13: =IF(AND(F13="Bilbo",E13<>"",G13<>"",H13<>""),E13&"|"&G13&"|"&H13,"") | Y13: =IF(B13="","",IF(B13<>B12,1,0))
A14: =IF(B14="","",ROW()-4) | C14: =IF(B14="","",CHOOSE(WEEKDAY(B14,2),"LUNES","MARTES","MIÉRCOLES","JUEVES","VIERNES","SÁBADO","DOMINGO")) | Q14: =IF(OR(K14="",N14=""),"",K14-N14) | R14: =IF(OR(J14="",K14=""),"",J14*K14) | S14: =IF(AND(ISNUMBER(J14),ISNUMBER(K14),F14<>"Calentamiento",F14<>"Bilbo"),IF(AND(K14>0,K14<=12),ROUND(J14*(1+(K14+IF(ISNUMBER(L14),L14,0))/30),1),""),"") | T14: =IF(AND(F14="Bilbo",ISNUMBER(J14),ISNUMBER(K14)),ROUND(J14*(1+K14/30),1),"") | X14: =IF(AND(F14="Bilbo",E14<>"",G14<>"",H14<>""),E14&"|"&G14&"|"&H14,"") | Y14: =IF(B14="","",IF(B14<>B13,1,0))
A15: =IF(B15="","",ROW()-4) | C15: =IF(B15="","",CHOOSE(WEEKDAY(B15,2),"LUNES","MARTES","MIÉRCOLES","JUEVES","VIERNES","SÁBADO","DOMINGO")) | Q15: =IF(OR(K15="",N15=""),"",K15-N15) | R15: =IF(OR(J15="",K15=""),"",J15*K15) | S15: =IF(AND(ISNUMBER(J15),ISNUMBER(K15),F15<>"Calentamiento",F15<>"Bilbo"),IF(AND(K15>0,K15<=12),ROUND(J15*(1+(K15+IF(ISNUMBER(L15),L15,0))/30),1),""),"") | T15: =IF(AND(F15="Bilbo",ISNUMBER(J15),ISNUMBER(K15)),ROUND(J15*(1+K15/30),1),"") | X15: =IF(AND(F15="Bilbo",E15<>"",G15<>"",H15<>""),E15&"|"&G15&"|"&H15,"") | Y15: =IF(B15="","",IF(B15<>B14,1,0))
A16: =IF(B16="","",ROW()-4) | C16: =IF(B16="","",CHOOSE(WEEKDAY(B16,2),"LUNES","MARTES","MIÉRCOLES","JUEVES","VIERNES","SÁBADO","DOMINGO")) | Q16: =IF(OR(K16="",N16=""),"",K16-N16) | R16: =IF(OR(J16="",K16=""),"",J16*K16) | S16: =IF(AND(ISNUMBER(J16),ISNUMBER(K16),F16<>"Calentamiento",F16<>"Bilbo"),IF(AND(K16>0,K16<=12),ROUND(J16*(1+(K16+IF(ISNUMBER(L16),L16,0))/30),1),""),"") | T16: =IF(AND(F16="Bilbo",ISNUMBER(J16),ISNUMBER(K16)),ROUND(J16*(1+K16/30),1),"") | X16: =IF(AND(F16="Bilbo",E16<>"",G16<>"",H16<>""),E16&"|"&G16&"|"&H16,"") | Y16: =IF(B16="","",IF(B16<>B15,1,0))
A17: =IF(B17="","",ROW()-4) | C17: =IF(B17="","",CHOOSE(WEEKDAY(B17,2),"LUNES","MARTES","MIÉRCOLES","JUEVES","VIERNES","SÁBADO","DOMINGO")) | Q17: =IF(OR(K17="",N17=""),"",K17-N17) | R17: =IF(OR(J17="",K17=""),"",J17*K17) | S17: =IF(AND(ISNUMBER(J17),ISNUMBER(K17),F17<>"Calentamiento",F17<>"Bilbo"),IF(AND(K17>0,K17<=12),ROUND(J17*(1+(K17+IF(ISNUMBER(L17),L17,0))/30),1),""),"") | T17: =IF(AND(F17="Bilbo",ISNUMBER(J17),ISNUMBER(K17)),ROUND(J17*(1+K17/30),1),"") | X17: =IF(AND(F17="Bilbo",E17<>"",G17<>"",H17<>""),E17&"|"&G17&"|"&H17,"") | Y17: =IF(B17="","",IF(B17<>B16,1,0))
... A2004: =IF(B2004="","",ROW()-4) | C2004: =IF(B2004="","",CHOOSE(WEEKDAY(B2004,2),"LUNES","MARTES","MIÉRCOLES","JUEVES","VIERNES","SÁBADO","DOMINGO")) | Q2004: =IF(OR(K2004="",N2004=""),"",K2004-N2004) | R2004: =IF(OR(J2004="",K2004=""),"",J2004*K2004) | S2004: =IF(AND(ISNUMBER(J2004),ISNUMBER(K2004),F2004<>"Calentamiento",F2004<>"Bilbo"),IF(AND(K2004>0,K2004<=12),ROUND(J2004*(1+(K2004+IF(ISNUMBER(L2004),L2004,0))/30),1),""),"") | T2004: =IF(AND(F2004="Bilbo",ISNUMBER(J2004),ISNUMBER(K2004)),ROUND(J2004*(1+K2004/30),1),"") | X2004: =IF(AND(F2004="Bilbo",E2004<>"",G2004<>"",H2004<>""),E2004&"|"&G2004&"|"&H2004,"") | Y2004: =IF(B2004="","",IF(B2004<>B2003,1,0))

Sheet ESTADO ACTUAL
A1: ESTADO ACTUAL — situación vigente de los ejercicios Bilbo (SE ACTUALIZA)
A2: Las columnas de decisión (amarillas) las rellena la IA tras cada sesión. El resto se calcula desde HISTORIAL y CONFIGURACIÓN.
A3: Leyenda: celdas AMARILLAS con texto AZUL = entrada/decisión (se editan). Celdas GRISES = fórmula (no tocar). Texto VERDE = vínculo a otra hoja (no tocar).
A4: EJERCICIO / CICLO | F4: DATOS DEL CICLO Y ÚLTIMA SESIÓN (HISTORIAL) | N4: PRÓXIMA SESIÓN BILBO | U4: POST-BILBO (3×8–12 @RIR1) | AG4: NOTAS / AUXILIARES
A5: Ejercicio | B5: Incremento (kg) | C5: Ciclo actual (DECISIÓN) | D5: Sesiones Bilbo hechas en el ciclo | E5: Posición próxima sesión | F5: Carga inicial del ciclo | G5: Reps iniciales del ciclo | H5: Fecha último Bilbo | I5: Último peso Bilbo | J5: Últimas reps Bilbo | K5: Reps estimadas (última) | L5: Dif. real − estimada | M5: Caída reps/kg (modelo) | N5: Próximo peso Bilbo SUGERIDO (fórmula) | O5: Próximo peso Bilbo DECISIÓN | P5: Reps esperadas (modelo) | Q5: Reps esperadas AJUSTE IA (opcional) | R5: Reps esperadas FINAL | S5: Estado del ciclo | T5: Fecha próxima sesión | U5: % post usado última sesión | V5: Fecha último post-Bilbo | W5: Peso post último | X5: Post S1 reps | Y5: Post S2 reps | Z5: Post S3 reps | AA5: RIR mín post | AB5: Último resultado post | AC5: Evaluación post (regla %) | AD5: % post SUGERIDO | AE5: % post próxima DECISIÓN | AF5: Peso post-Bilbo próxima (3×8–12 @RIR1) | AG5: Observaciones | AH5: aux: ID último Bilbo | AI5: aux: ID 1er Bilbo del ciclo | AJ5: aux: ID último post
A6: Press banca | B6: =INDEX(CONFIGURACIÓN!$H$42:$H$56,MATCH(A6,CONFIGURACIÓN!$B$42:$B$56,0)) -> 2 | C6: 1 | D6: =COUNTIFS(HISTORIAL!$E$5:$E$2004,A6,HISTORIAL!$F$5:$F$2004,"Bilbo",HISTORIAL!$G$5:$G$2004,C6) -> 0 | E6: ="Ciclo "&C6&" · sesión "&(D6+1) -> Ciclo 1 · sesión 1 | F6: =IF(AI6=0,"",INDEX(HISTORIAL!$J$5:$J$2004,AI6)) | G6: =IF(AI6=0,"",INDEX(HISTORIAL!$K$5:$K$2004,AI6)) | H6: =IF(AH6=0,"",INDEX(HISTORIAL!$B$5:$B$2004,AH6)) | I6: =IF(AH6=0,"",INDEX(HISTORIAL!$J$5:$J$2004,AH6)) | J6: =IF(AH6=0,"",INDEX(HISTORIAL!$K$5:$K$2004,AH6)) | K6: =IF(AH6=0,"",IF(INDEX(HISTORIAL!$N$5:$N$2004,AH6)="","",INDEX(HISTORIAL!$N$5:$N$2004,AH6))) | L6: =IF(OR(J6="",K6=""),"",J6-K6) | M6: =IF(AND(D6>=2,ISNUMBER(F6),ISNUMBER(I6),ISNUMBER(G6),ISNUMBER(J6)),IF(I6<>F6,MAX(CONFIGURACIÓN!$C$15,ROUND((G6-J6)/(I6-F6),2)),CONFIGURACIÓN!$C$14),CONFIGURACIÓN!$C$14) -> 1.5 | N6: =IF(I6="","CALIBRAR",IF(D6=0,"Inicio ciclo "&C6&": usar DECISIÓN",IF(J6<=CONFIGURACIÓN!$C$11,MAX(F6+B6,-INT(-F6*(1+CONFIGURACIÓN!$C$17)/B6)*B6),IF(AND(ISNUMBER(L6),L6<=-CONFIGURACIÓN!$C$18),I6,I6+B6)))) -> CALIBRAR | P6: =IF(NOT(ISNUMBER(O6)),"",IF(NOT(ISNUMBER(I6)),"30–40 (calibración)",MAX(1,ROUND(J6-M6*(O6-I6),0)))) | R6: =IF(Q6<>"",Q6,P6) | S6: =IF(I6="","SIN DATOS · sesión de calibración",IF(D6=0,"NUEVO CICLO "&C6&" PREPARADO",IF(J6<=CONFIGURACIÓN!$C$11,"CICLO TERMINADO · cerrar ciclo "&C6&" e iniciar ciclo "&(C6+1),IF(AND(ISNUMBER(L6),L6<=-CONFIGURACIÓN!$C$18),"RENDIMIENTO BAJO · analizar fatiga (no subir automáticamente)",IF(AND(ISNUMBER(R6),R6<=CONFIGURACIÓN!$C$11),"ÚLTIMA SESIÓN DEL CICLO PROBABLE",IF(J6<=CONFIGURACIÓN!$C$13,"PRÓXIMO A TERMINAR","EN PROGRESIÓN")))))) -> SIN DATOS · sesión de calibración | T6: =IF(ISNUMBER(INDEX(CONFIGURACIÓN!$K$42:$K$56,MATCH(A6,CONFIGURACIÓN!$B$42:$B$56,0))),IF(WEEKDAY(MAX(IF(ISNUMBER(H6),H6,0),TODAY()-1),2)<INDEX(CONFIGURACIÓN!$K$42:$K$56,MATCH(A6,CONFIGURACIÓN!$B$42:$B$56,0)),MAX(IF(ISNUMBER(H6),H6,0),TODAY()-1)+INDEX(CONFIGURACIÓN!$K$42:$K$56,MATCH(A6,CONFIGURACIÓN!$B$42:$B$56,0))-WEEKDAY(MAX(IF(ISNUMBER(H6),H6,0),TODAY()-1),2),IF(WEEKDAY(MAX(IF(ISNUMBER(H6),H6,0),TODAY()-1),2)<IF(ISNUMBER(INDEX(CONFIGURACIÓN!$L$42:$L$56,MATCH(A6,CONFIGURACIÓN!$B$42:$B$56,0))),INDEX(CONFIGURACIÓN!$L$42:$L$56,MATCH(A6,CONFIGURACIÓN!$B$42:$B$56,0)),INDEX(CONFIGURACIÓN!$K$42:$K$56,MATCH(A6,CONFIGURACIÓN!$B$42:$B$56,0))),MAX(IF(ISNUMBER(H6),H6,0),TODAY()-1)+IF(ISNUMBER(INDEX(CONFIGURACIÓN!$L$42:$L$56,MATCH(A6,CONFIGURACIÓN!$B$42:$B$56,0))),INDEX(CONFIGURACIÓN!$L$42:$L$56,MATCH(A6,CONFIGURACIÓN!$B$42:$B$56,0)),INDEX(CONFIGURACIÓN!$K$42:$K$56,MATCH(A6,CONFIGURACIÓN!$B$42:$B$56,0)))-WEEKDAY(MAX(IF(ISNUMBER(H6),H6,0),TODAY()-1),2),MAX(IF(ISNUMBER(H6),H6,0),TODAY()-1)+7-WEEKDAY(MAX(IF(ISNUMBER(H6),H6,0),TODAY()-1),2)+INDEX(CONFIGURACIÓN!$K$42:$K$56,MATCH(A6,CONFIGURACIÓN!$B$42:$B$56,0)))),"") -> 46293 | U6: =IF(AJ6=0,"",INDEX(HISTORIAL!$M$5:$M$2004,AJ6)) | V6: =IF(AJ6=0,"",INDEX(HISTORIAL!$B$5:$B$2004,AJ6)) | W6: =IF(AJ6=0,"",INDEX(HISTORIAL!$J$5:$J$2004,AJ6)) | X6: =IF(V6="","",SUMIFS(HISTORIAL!$K$5:$K$2004,HISTORIAL!$E$5:$E$2004,A6,HISTORIAL!$F$5:$F$2004,"Post-Bilbo",HISTORIAL!$B$5:$B$2004,V6,HISTORIAL!$I$5:$I$2004,1)) | Y6: =IF(V6="","",SUMIFS(HISTORIAL!$K$5:$K$2004,HISTORIAL!$E$5:$E$2004,A6,HISTORIAL!$F$5:$F$2004,"Post-Bilbo",HISTORIAL!$B$5:$B$2004,V6,HISTORIAL!$I$5:$I$2004,2)) | Z6: =IF(V6="","",SUMIFS(HISTORIAL!$K$5:$K$2004,HISTORIAL!$E$5:$E$2004,A6,HISTORIAL!$F$5:$F$2004,"Post-Bilbo",HISTORIAL!$B$5:$B$2004,V6,HISTORIAL!$I$5:$I$2004,3)) | AA6: =IF(V6="","",_xlfn.MINIFS(HISTORIAL!$L$5:$L$2004,HISTORIAL!$E$5:$E$2004,A6,HISTORIAL!$F$5:$F$2004,"Post-Bilbo",HISTORIAL!$B$5:$B$2004,V6)) | AB6: =IF(V6="","",W6&" kg × "&X6&" / "&Y6&" / "&Z6&" @RIR≥"&AA6) | AC6: =IF(V6="","SIN DATOS",IF(MIN(X6:Z6)<CONFIGURACIÓN!$C$20,"BAJAR %",IF(MIN(X6:Z6)>CONFIGURACIÓN!$C$21,"SUBIR %",IF(X6-Z6>=CONFIGURACIÓN!$C$27,"MANTENER · caída alta entre series","MANTENER")))) -> SIN DATOS | AD6: =IF(NOT(ISNUMBER(U6)),CONFIGURACIÓN!$C$23,MIN(CONFIGURACIÓN!$C$26,MAX(CONFIGURACIÓN!$C$25,U6+IF(AC6="SUBIR %",CONFIGURACIÓN!$C$24,IF(AC6="BAJAR %",-CONFIGURACIÓN!$C$24,0))))) -> 0.15 | AE6: 0.15 | AF6: =IF(AND(ISNUMBER(O6),ISNUMBER(AE6)),IF(CONFIGURACIÓN!$C$9="ABAJO",INT((O6*(1+AE6))/(B6))*(B6),IF(CONFIGURACIÓN!$C$9="ARRIBA",-INT(-(O6*(1+AE6))/(B6))*(B6),ROUND((O6*(1+AE6))/(B6),0)*(B6))),"") | AG6: Sin datos todavía. Primera sesión = calibración (ver INSTRUCCIONES §21). | AH6: =_xlfn.MAXIFS(HISTORIAL!$A$5:$A$2004,HISTORIAL!$E$5:$E$2004,A6,HISTORIAL!$F$5:$F$2004,"Bilbo") -> 0 | AI6: =_xlfn.MINIFS(HISTORIAL!$A$5:$A$2004,HISTORIAL!$E$5:$E$2004,A6,HISTORIAL!$F$5:$F$2004,"Bilbo",HISTORIAL!$G$5:$G$2004,C6) -> 0 | AJ6: =_xlfn.MAXIFS(HISTORIAL!$A$5:$A$2004,HISTORIAL!$E$5:$E$2004,A6,HISTORIAL!$F$5:$F$2004,"Post-Bilbo") -> 0
A7: Press militar | B7: =INDEX(CONFIGURACIÓN!$H$42:$H$56,MATCH(A7,CONFIGURACIÓN!$B$42:$B$56,0)) -> 2 | C7: 1 | D7: =COUNTIFS(HISTORIAL!$E$5:$E$2004,A7,HISTORIAL!$F$5:$F$2004,"Bilbo",HISTORIAL!$G$5:$G$2004,C7) -> 0 | E7: ="Ciclo "&C7&" · sesión "&(D7+1) -> Ciclo 1 · sesión 1 | F7: =IF(AI7=0,"",INDEX(HISTORIAL!$J$5:$J$2004,AI7)) | G7: =IF(AI7=0,"",INDEX(HISTORIAL!$K$5:$K$2004,AI7)) | H7: =IF(AH7=0,"",INDEX(HISTORIAL!$B$5:$B$2004,AH7)) | I7: =IF(AH7=0,"",INDEX(HISTORIAL!$J$5:$J$2004,AH7)) | J7: =IF(AH7=0,"",INDEX(HISTORIAL!$K$5:$K$2004,AH7)) | K7: =IF(AH7=0,"",IF(INDEX(HISTORIAL!$N$5:$N$2004,AH7)="","",INDEX(HISTORIAL!$N$5:$N$2004,AH7))) | L7: =IF(OR(J7="",K7=""),"",J7-K7) | M7: =IF(AND(D7>=2,ISNUMBER(F7),ISNUMBER(I7),ISNUMBER(G7),ISNUMBER(J7)),IF(I7<>F7,MAX(CONFIGURACIÓN!$C$15,ROUND((G7-J7)/(I7-F7),2)),CONFIGURACIÓN!$C$14),CONFIGURACIÓN!$C$14) -> 1.5 | N7: =IF(I7="","CALIBRAR",IF(D7=0,"Inicio ciclo "&C7&": usar DECISIÓN",IF(J7<=CONFIGURACIÓN!$C$11,MAX(F7+B7,-INT(-F7*(1+CONFIGURACIÓN!$C$17)/B7)*B7),IF(AND(ISNUMBER(L7),L7<=-CONFIGURACIÓN!$C$18),I7,I7+B7)))) -> CALIBRAR | P7: =IF(NOT(ISNUMBER(O7)),"",IF(NOT(ISNUMBER(I7)),"30–40 (calibración)",MAX(1,ROUND(J7-M7*(O7-I7),0)))) | R7: =IF(Q7<>"",Q7,P7) | S7: =IF(I7="","SIN DATOS · sesión de calibración",IF(D7=0,"NUEVO CICLO "&C7&" PREPARADO",IF(J7<=CONFIGURACIÓN!$C$11,"CICLO TERMINADO · cerrar ciclo "&C7&" e iniciar ciclo "&(C7+1),IF(AND(ISNUMBER(L7),L7<=-CONFIGURACIÓN!$C$18),"RENDIMIENTO BAJO · analizar fatiga (no subir automáticamente)",IF(AND(ISNUMBER(R7),R7<=CONFIGURACIÓN!$C$11),"ÚLTIMA SESIÓN DEL CICLO PROBABLE",IF(J7<=CONFIGURACIÓN!$C$13,"PRÓXIMO A TERMINAR","EN PROGRESIÓN")))))) -> SIN DATOS · sesión de calibración | T7: =IF(ISNUMBER(INDEX(CONFIGURACIÓN!$K$42:$K$56,MATCH(A7,CONFIGURACIÓN!$B$42:$B$56,0))),IF(WEEKDAY(MAX(IF(ISNUMBER(H7),H7,0),TODAY()-1),2)<INDEX(CONFIGURACIÓN!$K$42:$K$56,MATCH(A7,CONFIGURACIÓN!$B$42:$B$56,0)),MAX(IF(ISNUMBER(H7),H7,0),TODAY()-1)+INDEX(CONFIGURACIÓN!$K$42:$K$56,MATCH(A7,CONFIGURACIÓN!$B$42:$B$56,0))-WEEKDAY(MAX(IF(ISNUMBER(H7),H7,0),TODAY()-1),2),IF(WEEKDAY(MAX(IF(ISNUMBER(H7),H7,0),TODAY()-1),2)<IF(ISNUMBER(INDEX(CONFIGURACIÓN!$L$42:$L$56,MATCH(A7,CONFIGURACIÓN!$B$42:$B$56,0))),INDEX(CONFIGURACIÓN!$L$42:$L$56,MATCH(A7,CONFIGURACIÓN!$B$42:$B$56,0)),INDEX(CONFIGURACIÓN!$K$42:$K$56,MATCH(A7,CONFIGURACIÓN!$B$42:$B$56,0))),MAX(IF(ISNUMBER(H7),H7,0),TODAY()-1)+IF(ISNUMBER(INDEX(CONFIGURACIÓN!$L$42:$L$56,MATCH(A7,CONFIGURACIÓN!$B$42:$B$56,0))),INDEX(CONFIGURACIÓN!$L$42:$L$56,MATCH(A7,CONFIGURACIÓN!$B$42:$B$56,0)),INDEX(CONFIGURACIÓN!$K$42:$K$56,MATCH(A7,CONFIGURACIÓN!$B$42:$B$56,0)))-WEEKDAY(MAX(IF(ISNUMBER(H7),H7,0),TODAY()-1),2),MAX(IF(ISNUMBER(H7),H7,0),TODAY()-1)+7-WEEKDAY(MAX(IF(ISNUMBER(H7),H7,0),TODAY()-1),2)+INDEX(CONFIGURACIÓN!$K$42:$K$56,MATCH(A7,CONFIGURACIÓN!$B$42:$B$56,0)))),"") -> 46293 | U7: =IF(AJ7=0,"",INDEX(HISTORIAL!$M$5:$M$2004,AJ7)) | V7: =IF(AJ7=0,"",INDEX(HISTORIAL!$B$5:$B$2004,AJ7)) | W7: =IF(AJ7=0,"",INDEX(HISTORIAL!$J$5:$J$2004,AJ7)) | X7: =IF(V7="","",SUMIFS(HISTORIAL!$K$5:$K$2004,HISTORIAL!$E$5:$E$2004,A7,HISTORIAL!$F$5:$F$2004,"Post-Bilbo",HISTORIAL!$B$5:$B$2004,V7,HISTORIAL!$I$5:$I$2004,1)) | Y7: =IF(V7="","",SUMIFS(HISTORIAL!$K$5:$K$2004,HISTORIAL!$E$5:$E$2004,A7,HISTORIAL!$F$5:$F$2004,"Post-Bilbo",HISTORIAL!$B$5:$B$2004,V7,HISTORIAL!$I$5:$I$2004,2)) | Z7: =IF(V7="","",SUMIFS(HISTORIAL!$K$5:$K$2004,HISTORIAL!$E$5:$E$2004,A7,HISTORIAL!$F$5:$F$2004,"Post-Bilbo",HISTORIAL!$B$5:$B$2004,V7,HISTORIAL!$I$5:$I$2004,3)) | AA7: =IF(V7="","",_xlfn.MINIFS(HISTORIAL!$L$5:$L$2004,HISTORIAL!$E$5:$E$2004,A7,HISTORIAL!$F$5:$F$2004,"Post-Bilbo",HISTORIAL!$B$5:$B$2004,V7)) | AB7: =IF(V7="","",W7&" kg × "&X7&" / "&Y7&" / "&Z7&" @RIR≥"&AA7) | AC7: =IF(V7="","SIN DATOS",IF(MIN(X7:Z7)<CONFIGURACIÓN!$C$20,"BAJAR %",IF(MIN(X7:Z7)>CONFIGURACIÓN!$C$21,"SUBIR %",IF(X7-Z7>=CONFIGURACIÓN!$C$27,"MANTENER · caída alta entre series","MANTENER")))) -> SIN DATOS | AD7: =IF(NOT(ISNUMBER(U7)),CONFIGURACIÓN!$C$23,MIN(CONFIGURACIÓN!$C$26,MAX(CONFIGURACIÓN!$C$25,U7+IF(AC7="SUBIR %",CONFIGURACIÓN!$C$24,IF(AC7="BAJAR %",-CONFIGURACIÓN!$C$24,0))))) -> 0.15 | AE7: 0.15 | AF7: =IF(AND(ISNUMBER(O7),ISNUMBER(AE7)),IF(CONFIGURACIÓN!$C$9="ABAJO",INT((O7*(1+AE7))/(B7))*(B7),IF(CONFIGURACIÓN!$C$9="ARRIBA",-INT(-(O7*(1+AE7))/(B7))*(B7),ROUND((O7*(1+AE7))/(B7),0)*(B7))),"") | AG7: Sin datos todavía. Primera sesión = calibración (ver INSTRUCCIONES §21). | AH7: =_xlfn.MAXIFS(HISTORIAL!$A$5:$A$2004,HISTORIAL!$E$5:$E$2004,A7,HISTORIAL!$F$5:$F$2004,"Bilbo") -> 0 | AI7: =_xlfn.MINIFS(HISTORIAL!$A$5:$A$2004,HISTORIAL!$E$5:$E$2004,A7,HISTORIAL!$F$5:$F$2004,"Bilbo",HISTORIAL!$G$5:$G$2004,C7) -> 0 | AJ7: =_xlfn.MAXIFS(HISTORIAL!$A$5:$A$2004,HISTORIAL!$E$5:$E$2004,A7,HISTORIAL!$F$5:$F$2004,"Post-Bilbo") -> 0
A8: Remo bajo en polea | B8: =INDEX(CONFIGURACIÓN!$H$42:$H$56,MATCH(A8,CONFIGURACIÓN!$B$42:$B$56,0)) -> 2 | C8: 1 | D8: =COUNTIFS(HISTORIAL!$E$5:$E$2004,A8,HISTORIAL!$F$5:$F$2004,"Bilbo",HISTORIAL!$G$5:$G$2004,C8) -> 0 | E8: ="Ciclo "&C8&" · sesión "&(D8+1) -> Ciclo 1 · sesión 1 | F8: =IF(AI8=0,"",INDEX(HISTORIAL!$J$5:$J$2004,AI8)) | G8: =IF(AI8=0,"",INDEX(HISTORIAL!$K$5:$K$2004,AI8)) | H8: =IF(AH8=0,"",INDEX(HISTORIAL!$B$5:$B$2004,AH8)) | I8: =IF(AH8=0,"",INDEX(HISTORIAL!$J$5:$J$2004,AH8)) | J8: =IF(AH8=0,"",INDEX(HISTORIAL!$K$5:$K$2004,AH8)) | K8: =IF(AH8=0,"",IF(INDEX(HISTORIAL!$N$5:$N$2004,AH8)="","",INDEX(HISTORIAL!$N$5:$N$2004,AH8))) | L8: =IF(OR(J8="",K8=""),"",J8-K8) | M8: =IF(AND(D8>=2,ISNUMBER(F8),ISNUMBER(I8),ISNUMBER(G8),ISNUMBER(J8)),IF(I8<>F8,MAX(CONFIGURACIÓN!$C$15,ROUND((G8-J8)/(I8-F8),2)),CONFIGURACIÓN!$C$14),CONFIGURACIÓN!$C$14) -> 1.5 | N8: =IF(I8="","CALIBRAR",IF(D8=0,"Inicio ciclo "&C8&": usar DECISIÓN",IF(J8<=CONFIGURACIÓN!$C$11,MAX(F8+B8,-INT(-F8*(1+CONFIGURACIÓN!$C$17)/B8)*B8),IF(AND(ISNUMBER(L8),L8<=-CONFIGURACIÓN!$C$18),I8,I8+B8)))) -> CALIBRAR | P8: =IF(NOT(ISNUMBER(O8)),"",IF(NOT(ISNUMBER(I8)),"30–40 (calibración)",MAX(1,ROUND(J8-M8*(O8-I8),0)))) | R8: =IF(Q8<>"",Q8,P8) | S8: =IF(I8="","SIN DATOS · sesión de calibración",IF(D8=0,"NUEVO CICLO "&C8&" PREPARADO",IF(J8<=CONFIGURACIÓN!$C$11,"CICLO TERMINADO · cerrar ciclo "&C8&" e iniciar ciclo "&(C8+1),IF(AND(ISNUMBER(L8),L8<=-CONFIGURACIÓN!$C$18),"RENDIMIENTO BAJO · analizar fatiga (no subir automáticamente)",IF(AND(ISNUMBER(R8),R8<=CONFIGURACIÓN!$C$11),"ÚLTIMA SESIÓN DEL CICLO PROBABLE",IF(J8<=CONFIGURACIÓN!$C$13,"PRÓXIMO A TERMINAR","EN PROGRESIÓN")))))) -> SIN DATOS · sesión de calibración | T8: =IF(ISNUMBER(INDEX(CONFIGURACIÓN!$K$42:$K$56,MATCH(A8,CONFIGURACIÓN!$B$42:$B$56,0))),IF(WEEKDAY(MAX(IF(ISNUMBER(H8),H8,0),TODAY()-1),2)<INDEX(CONFIGURACIÓN!$K$42:$K$56,MATCH(A8,CONFIGURACIÓN!$B$42:$B$56,0)),MAX(IF(ISNUMBER(H8),H8,0),TODAY()-1)+INDEX(CONFIGURACIÓN!$K$42:$K$56,MATCH(A8,CONFIGURACIÓN!$B$42:$B$56,0))-WEEKDAY(MAX(IF(ISNUMBER(H8),H8,0),TODAY()-1),2),IF(WEEKDAY(MAX(IF(ISNUMBER(H8),H8,0),TODAY()-1),2)<IF(ISNUMBER(INDEX(CONFIGURACIÓN!$L$42:$L$56,MATCH(A8,CONFIGURACIÓN!$B$42:$B$56,0))),INDEX(CONFIGURACIÓN!$L$42:$L$56,MATCH(A8,CONFIGURACIÓN!$B$42:$B$56,0)),INDEX(CONFIGURACIÓN!$K$42:$K$56,MATCH(A8,CONFIGURACIÓN!$B$42:$B$56,0))),MAX(IF(ISNUMBER(H8),H8,0),TODAY()-1)+IF(ISNUMBER(INDEX(CONFIGURACIÓN!$L$42:$L$56,MATCH(A8,CONFIGURACIÓN!$B$42:$B$56,0))),INDEX(CONFIGURACIÓN!$L$42:$L$56,MATCH(A8,CONFIGURACIÓN!$B$42:$B$56,0)),INDEX(CONFIGURACIÓN!$K$42:$K$56,MATCH(A8,CONFIGURACIÓN!$B$42:$B$56,0)))-WEEKDAY(MAX(IF(ISNUMBER(H8),H8,0),TODAY()-1),2),MAX(IF(ISNUMBER(H8),H8,0),TODAY()-1)+7-WEEKDAY(MAX(IF(ISNUMBER(H8),H8,0),TODAY()-1),2)+INDEX(CONFIGURACIÓN!$K$42:$K$56,MATCH(A8,CONFIGURACIÓN!$B$42:$B$56,0)))),"") -> 46294 | U8: =IF(AJ8=0,"",INDEX(HISTORIAL!$M$5:$M$2004,AJ8)) | V8: =IF(AJ8=0,"",INDEX(HISTORIAL!$B$5:$B$2004,AJ8)) | W8: =IF(AJ8=0,"",INDEX(HISTORIAL!$J$5:$J$2004,AJ8)) | X8: =IF(V8="","",SUMIFS(HISTORIAL!$K$5:$K$2004,HISTORIAL!$E$5:$E$2004,A8,HISTORIAL!$F$5:$F$2004,"Post-Bilbo",HISTORIAL!$B$5:$B$2004,V8,HISTORIAL!$I$5:$I$2004,1)) | Y8: =IF(V8="","",SUMIFS(HISTORIAL!$K$5:$K$2004,HISTORIAL!$E$5:$E$2004,A8,HISTORIAL!$F$5:$F$2004,"Post-Bilbo",HISTORIAL!$B$5:$B$2004,V8,HISTORIAL!$I$5:$I$2004,2)) | Z8: =IF(V8="","",SUMIFS(HISTORIAL!$K$5:$K$2004,HISTORIAL!$E$5:$E$2004,A8,HISTORIAL!$F$5:$F$2004,"Post-Bilbo",HISTORIAL!$B$5:$B$2004,V8,HISTORIAL!$I$5:$I$2004,3)) | AA8: =IF(V8="","",_xlfn.MINIFS(HISTORIAL!$L$5:$L$2004,HISTORIAL!$E$5:$E$2004,A8,HISTORIAL!$F$5:$F$2004,"Post-Bilbo",HISTORIAL!$B$5:$B$2004,V8)) | AB8: =IF(V8="","",W8&" kg × "&X8&" / "&Y8&" / "&Z8&" @RIR≥"&AA8) | AC8: =IF(V8="","SIN DATOS",IF(MIN(X8:Z8)<CONFIGURACIÓN!$C$20,"BAJAR %",IF(MIN(X8:Z8)>CONFIGURACIÓN!$C$21,"SUBIR %",IF(X8-Z8>=CONFIGURACIÓN!$C$27,"MANTENER · caída alta entre series","MANTENER")))) -> SIN DATOS | AD8: =IF(NOT(ISNUMBER(U8)),CONFIGURACIÓN!$C$23,MIN(CONFIGURACIÓN!$C$26,MAX(CONFIGURACIÓN!$C$25,U8+IF(AC8="SUBIR %",CONFIGURACIÓN!$C$24,IF(AC8="BAJAR %",-CONFIGURACIÓN!$C$24,0))))) -> 0.15 | AE8: 0.15 | AF8: =IF(AND(ISNUMBER(O8),ISNUMBER(AE8)),IF(CONFIGURACIÓN!$C$9="ABAJO",INT((O8*(1+AE8))/(B8))*(B8),IF(CONFIGURACIÓN!$C$9="ARRIBA",-INT(-(O8*(1+AE8))/(B8))*(B8),ROUND((O8*(1+AE8))/(B8),0)*(B8))),"") | AG8: Sin datos todavía. Primera sesión = calibración (ver INSTRUCCIONES §21). | AH8: =_xlfn.MAXIFS(HISTORIAL!$A$5:$A$2004,HISTORIAL!$E$5:$E$2004,A8,HISTORIAL!$F$5:$F$2004,"Bilbo") -> 0 | AI8: =_xlfn.MINIFS(HISTORIAL!$A$5:$A$2004,HISTORIAL!$E$5:$E$2004,A8,HISTORIAL!$F$5:$F$2004,"Bilbo",HISTORIAL!$G$5:$G$2004,C8) -> 0 | AJ8: =_xlfn.MAXIFS(HISTORIAL!$A$5:$A$2004,HISTORIAL!$E$5:$E$2004,A8,HISTORIAL!$F$5:$F$2004,"Post-Bilbo") -> 0
A10: Cómo se usa: tras cada sesión la IA escribe en HISTORIAL y luego decide aquí 'Próximo peso Bilbo DECISIÓN', '% post próxima DECISIÓN' y, al cerrar un ciclo, 'Ciclo actual'. SUGERIDO es solo la propuesta automática; la DECISIÓN manda.
A11: Sin datos (calibración): 'Próximo peso Bilbo DECISIÓN' queda vacío hasta conocer la primera referencia. Columnas 'aux' = auxiliares técnicas (no tocar).

Sheet CICLOS BILBO
A1: CICLOS BILBO — todos los ciclos (NUNCA borrar ciclos anteriores)
A2: Para abrir un ciclo nuevo: escribir Ejercicio, Nº ciclo y Estado=ACTIVO en la primera fila libre (el resto se calcula). Marcar el anterior como TERMINADO.
A3: Leyenda: celdas AMARILLAS con texto AZUL = entrada/decisión (se editan). Celdas GRISES = fórmula (no tocar). Texto VERDE = vínculo a otra hoja (no tocar).
A5: Ejercicio | B5: Nº ciclo | C5: Estado | D5: Fecha inicio | E5: Peso inicial | F5: Reps iniciales | G5: Fecha última / fin | H5: Peso final (último) | I5: Reps finales (últimas) | J5: Nº sesiones | K5: Mayor carga del ciclo | L5: Reps con esa carga | M5: Mejor índice Bilbo | N5: Progreso de carga en el ciclo (kg) | O5: Peso inicial ciclo anterior | P5: Regla: inicial > anterior | Q5: Reps en ciclo anterior con la carga inicial de este | R5: Mejora de reps a igual carga | S5: Volumen del ciclo (Bilbo+post, kg) | T5: Carga inicial ciclo siguiente SUGERIDA | U5: Carga inicial ciclo siguiente DECISIÓN | V5: Validación decisión | W5: Observaciones / análisis
A6: Press banca | B6: 1 | C6: ACTIVO | D6: =IF($A6="","",IF(_xlfn.MINIFS(HISTORIAL!$A$5:$A$2004,HISTORIAL!$E$5:$E$2004,$A6,HISTORIAL!$F$5:$F$2004,"Bilbo",HISTORIAL!$G$5:$G$2004,$B6)=0,"",INDEX(HISTORIAL!$B$5:$B$2004,_xlfn.MINIFS(HISTORIAL!$A$5:$A$2004,HISTORIAL!$E$5:$E$2004,$A6,HISTORIAL!$F$5:$F$2004,"Bilbo",HISTORIAL!$G$5:$G$2004,$B6)))) | E6: =IF($A6="","",IF(_xlfn.MINIFS(HISTORIAL!$A$5:$A$2004,HISTORIAL!$E$5:$E$2004,$A6,HISTORIAL!$F$5:$F$2004,"Bilbo",HISTORIAL!$G$5:$G$2004,$B6)=0,"",INDEX(HISTORIAL!$J$5:$J$2004,_xlfn.MINIFS(HISTORIAL!$A$5:$A$2004,HISTORIAL!$E$5:$E$2004,$A6,HISTORIAL!$F$5:$F$2004,"Bilbo",HISTORIAL!$G$5:$G$2004,$B6)))) | F6: =IF($A6="","",IF(_xlfn.MINIFS(HISTORIAL!$A$5:$A$2004,HISTORIAL!$E$5:$E$2004,$A6,HISTORIAL!$F$5:$F$2004,"Bilbo",HISTORIAL!$G$5:$G$2004,$B6)=0,"",INDEX(HISTORIAL!$K$5:$K$2004,_xlfn.MINIFS(HISTORIAL!$A$5:$A$2004,HISTORIAL!$E$5:$E$2004,$A6,HISTORIAL!$F$5:$F$2004,"Bilbo",HISTORIAL!$G$5:$G$2004,$B6)))) | G6: =IF($A6="","",IF(_xlfn.MAXIFS(HISTORIAL!$A$5:$A$2004,HISTORIAL!$E$5:$E$2004,$A6,HISTORIAL!$F$5:$F$2004,"Bilbo",HISTORIAL!$G$5:$G$2004,$B6)=0,"",INDEX(HISTORIAL!$B$5:$B$2004,_xlfn.MAXIFS(HISTORIAL!$A$5:$A$2004,HISTORIAL!$E$5:$E$2004,$A6,HISTORIAL!$F$5:$F$2004,"Bilbo",HISTORIAL!$G$5:$G$2004,$B6)))) | H6: =IF($A6="","",IF(_xlfn.MAXIFS(HISTORIAL!$A$5:$A$2004,HISTORIAL!$E$5:$E$2004,$A6,HISTORIAL!$F$5:$F$2004,"Bilbo",HISTORIAL!$G$5:$G$2004,$B6)=0,"",INDEX(HISTORIAL!$J$5:$J$2004,_xlfn.MAXIFS(HISTORIAL!$A$5:$A$2004,HISTORIAL!$E$5:$E$2004,$A6,HISTORIAL!$F$5:$F$2004,"Bilbo",HISTORIAL!$G$5:$G$2004,$B6)))) | I6: =IF($A6="","",IF(_xlfn.MAXIFS(HISTORIAL!$A$5:$A$2004,HISTORIAL!$E$5:$E$2004,$A6,HISTORIAL!$F$5:$F$2004,"Bilbo",HISTORIAL!$G$5:$G$2004,$B6)=0,"",INDEX(HISTORIAL!$K$5:$K$2004,_xlfn.MAXIFS(HISTORIAL!$A$5:$A$2004,HISTORIAL!$E$5:$E$2004,$A6,HISTORIAL!$F$5:$F$2004,"Bilbo",HISTORIAL!$G$5:$G$2004,$B6)))) | J6: =IF($A6="","",COUNTIFS(HISTORIAL!$E$5:$E$2004,$A6,HISTORIAL!$F$5:$F$2004,"Bilbo",HISTORIAL!$G$5:$G$2004,$B6)) -> 0 | K6: =IF($A6="","",IF(J6=0,"",_xlfn.MAXIFS(HISTORIAL!$J$5:$J$2004,HISTORIAL!$E$5:$E$2004,$A6,HISTORIAL!$F$5:$F$2004,"Bilbo",HISTORIAL!$G$5:$G$2004,$B6))) | L6: =IF($A6="","",IF(J6=0,"",_xlfn.MAXIFS(HISTORIAL!$K$5:$K$2004,HISTORIAL!$E$5:$E$2004,$A6,HISTORIAL!$F$5:$F$2004,"Bilbo",HISTORIAL!$G$5:$G$2004,$B6,HISTORIAL!$J$5:$J$2004,K6))) | M6: =IF($A6="","",IF(J6=0,"",_xlfn.MAXIFS(HISTORIAL!$T$5:$T$2004,HISTORIAL!$E$5:$E$2004,$A6,HISTORIAL!$F$5:$F$2004,"Bilbo",HISTORIAL!$G$5:$G$2004,$B6))) | N6: =IF($A6="","",IF(J6=0,"",H6-E6)) | O6: =IF($A6="","",IF(COUNTIFS($A$6:$A$105,$A6,$B$6:$B$105,$B6-1)=0,"",SUMIFS($E$6:$E$105,$A$6:$A$105,$A6,$B$6:$B$105,$B6-1))) | P6: =IF($A6="","",IF(OR(O6="",NOT(ISNUMBER(E6))),"—",IF(E6>O6,"OK","ERROR: debe ser > "&O6))) -> — | Q6: =IF($A6="","",IF(OR(O6="",NOT(ISNUMBER(E6))),"",IF(_xlfn.MAXIFS(HISTORIAL!$K$5:$K$2004,HISTORIAL!$E$5:$E$2004,$A6,HISTORIAL!$F$5:$F$2004,"Bilbo",HISTORIAL!$G$5:$G$2004,$B6-1,HISTORIAL!$J$5:$J$2004,E6)=0,"sin dato comparable",_xlfn.MAXIFS(HISTORIAL!$K$5:$K$2004,HISTORIAL!$E$5:$E$2004,$A6,HISTORIAL!$F$5:$F$2004,"Bilbo",HISTORIAL!$G$5:$G$2004,$B6-1,HISTORIAL!$J$5:$J$2004,E6)))) | R6: =IF($A6="","",IF(AND(ISNUMBER(Q6),ISNUMBER(F6)),F6-Q6,"")) | S6: =IF($A6="","",SUMIFS(HISTORIAL!$R$5:$R$2004,HISTORIAL!$E$5:$E$2004,$A6,HISTORIAL!$F$5:$F$2004,"Bilbo",HISTORIAL!$G$5:$G$2004,$B6)+SUMIFS(HISTORIAL!$R$5:$R$2004,HISTORIAL!$E$5:$E$2004,$A6,HISTORIAL!$F$5:$F$2004,"Post-Bilbo",HISTORIAL!$G$5:$G$2004,$B6)) -> 0 | T6: =IF($A6="","",IF(NOT(ISNUMBER(E6)),"",MAX(E6+INDEX(CONFIGURACIÓN!$H$42:$H$56,MATCH($A6,CONFIGURACIÓN!$B$42:$B$56,0)),-INT(-E6*(1+CONFIGURACIÓN!$C$17)/(INDEX(CONFIGURACIÓN!$H$42:$H$56,MATCH($A6,CONFIGURACIÓN!$B$42:$B$56,0))))*(INDEX(CONFIGURACIÓN!$H$42:$H$56,MATCH($A6,CONFIGURACIÓN!$B$42:$B$56,0)))))) | V6: =IF($A6="","",IF(U6="","",IF(NOT(ISNUMBER(E6)),"sin carga inicial registrada",IF(U6>E6,"OK","ERROR: debe ser > "&E6)))) | W6: Ciclo 1 abierto al crear el sistema (27/09/2026). Primera sesión = calibración.
A7: Press militar | B7: 1 | C7: ACTIVO | D7: =IF($A7="","",IF(_xlfn.MINIFS(HISTORIAL!$A$5:$A$2004,HISTORIAL!$E$5:$E$2004,$A7,HISTORIAL!$F$5:$F$2004,"Bilbo",HISTORIAL!$G$5:$G$2004,$B7)=0,"",INDEX(HISTORIAL!$B$5:$B$2004,_xlfn.MINIFS(HISTORIAL!$A$5:$A$2004,HISTORIAL!$E$5:$E$2004,$A7,HISTORIAL!$F$5:$F$2004,"Bilbo",HISTORIAL!$G$5:$G$2004,$B7)))) | E7: =IF($A7="","",IF(_xlfn.MINIFS(HISTORIAL!$A$5:$A$2004,HISTORIAL!$E$5:$E$2004,$A7,HISTORIAL!$F$5:$F$2004,"Bilbo",HISTORIAL!$G$5:$G$2004,$B7)=0,"",INDEX(HISTORIAL!$J$5:$J$2004,_xlfn.MINIFS(HISTORIAL!$A$5:$A$2004,HISTORIAL!$E$5:$E$2004,$A7,HISTORIAL!$F$5:$F$2004,"Bilbo",HISTORIAL!$G$5:$G$2004,$B7)))) | F7: =IF($A7="","",IF(_xlfn.MINIFS(HISTORIAL!$A$5:$A$2004,HISTORIAL!$E$5:$E$2004,$A7,HISTORIAL!$F$5:$F$2004,"Bilbo",HISTORIAL!$G$5:$G$2004,$B7)=0,"",INDEX(HISTORIAL!$K$5:$K$2004,_xlfn.MINIFS(HISTORIAL!$A$5:$A$2004,HISTORIAL!$E$5:$E$2004,$A7,HISTORIAL!$F$5:$F$2004,"Bilbo",HISTORIAL!$G$5:$G$2004,$B7)))) | G7: =IF($A7="","",IF(_xlfn.MAXIFS(HISTORIAL!$A$5:$A$2004,HISTORIAL!$E$5:$E$2004,$A7,HISTORIAL!$F$5:$F$2004,"Bilbo",HISTORIAL!$G$5:$G$2004,$B7)=0,"",INDEX(HISTORIAL!$B$5:$B$2004,_xlfn.MAXIFS(HISTORIAL!$A$5:$A$2004,HISTORIAL!$E$5:$E$2004,$A7,HISTORIAL!$F$5:$F$2004,"Bilbo",HISTORIAL!$G$5:$G$2004,$B7)))) | H7: =IF($A7="","",IF(_xlfn.MAXIFS(HISTORIAL!$A$5:$A$2004,HISTORIAL!$E$5:$E$2004,$A7,HISTORIAL!$F$5:$F$2004,"Bilbo",HISTORIAL!$G$5:$G$2004,$B7)=0,"",INDEX(HISTORIAL!$J$5:$J$2004,_xlfn.MAXIFS(HISTORIAL!$A$5:$A$2004,HISTORIAL!$E$5:$E$2004,$A7,HISTORIAL!$F$5:$F$2004,"Bilbo",HISTORIAL!$G$5:$G$2004,$B7)))) | I7: =IF($A7="","",IF(_xlfn.MAXIFS(HISTORIAL!$A$5:$A$2004,HISTORIAL!$E$5:$E$2004,$A7,HISTORIAL!$F$5:$F$2004,"Bilbo",HISTORIAL!$G$5:$G$2004,$B7)=0,"",INDEX(HISTORIAL!$K$5:$K$2004,_xlfn.MAXIFS(HISTORIAL!$A$5:$A$2004,HISTORIAL!$E$5:$E$2004,$A7,HISTORIAL!$F$5:$F$2004,"Bilbo",HISTORIAL!$G$5:$G$2004,$B7)))) | J7: =IF($A7="","",COUNTIFS(HISTORIAL!$E$5:$E$2004,$A7,HISTORIAL!$F$5:$F$2004,"Bilbo",HISTORIAL!$G$5:$G$2004,$B7)) -> 0 | K7: =IF($A7="","",IF(J7=0,"",_xlfn.MAXIFS(HISTORIAL!$J$5:$J$2004,HISTORIAL!$E$5:$E$2004,$A7,HISTORIAL!$F$5:$F$2004,"Bilbo",HISTORIAL!$G$5:$G$2004,$B7))) | L7: =IF($A7="","",IF(J7=0,"",_xlfn.MAXIFS(HISTORIAL!$K$5:$K$2004,HISTORIAL!$E$5:$E$2004,$A7,HISTORIAL!$F$5:$F$2004,"Bilbo",HISTORIAL!$G$5:$G$2004,$B7,HISTORIAL!$J$5:$J$2004,K7))) | M7: =IF($A7="","",IF(J7=0,"",_xlfn.MAXIFS(HISTORIAL!$T$5:$T$2004,HISTORIAL!$E$5:$E$2004,$A7,HISTORIAL!$F$5:$F$2004,"Bilbo",HISTORIAL!$G$5:$G$2004,$B7))) | N7: =IF($A7="","",IF(J7=0,"",H7-E7)) | O7: =IF($A7="","",IF(COUNTIFS($A$6:$A$105,$A7,$B$6:$B$105,$B7-1)=0,"",SUMIFS($E$6:$E$105,$A$6:$A$105,$A7,$B$6:$B$105,$B7-1))) | P7: =IF($A7="","",IF(OR(O7="",NOT(ISNUMBER(E7))),"—",IF(E7>O7,"OK","ERROR: debe ser > "&O7))) -> — | Q7: =IF($A7="","",IF(OR(O7="",NOT(ISNUMBER(E7))),"",IF(_xlfn.MAXIFS(HISTORIAL!$K$5:$K$2004,HISTORIAL!$E$5:$E$2004,$A7,HISTORIAL!$F$5:$F$2004,"Bilbo",HISTORIAL!$G$5:$G$2004,$B7-1,HISTORIAL!$J$5:$J$2004,E7)=0,"sin dato comparable",_xlfn.MAXIFS(HISTORIAL!$K$5:$K$2004,HISTORIAL!$E$5:$E$2004,$A7,HISTORIAL!$F$5:$F$2004,"Bilbo",HISTORIAL!$G$5:$G$2004,$B7-1,HISTORIAL!$J$5:$J$2004,E7)))) | R7: =IF($A7="","",IF(AND(ISNUMBER(Q7),ISNUMBER(F7)),F7-Q7,"")) | S7: =IF($A7="","",SUMIFS(HISTORIAL!$R$5:$R$2004,HISTORIAL!$E$5:$E$2004,$A7,HISTORIAL!$F$5:$F$2004,"Bilbo",HISTORIAL!$G$5:$G$2004,$B7)+SUMIFS(HISTORIAL!$R$5:$R$2004,HISTORIAL!$E$5:$E$2004,$A7,HISTORIAL!$F$5:$F$2004,"Post-Bilbo",HISTORIAL!$G$5:$G$2004,$B7)) -> 0 | T7: =IF($A7="","",IF(NOT(ISNUMBER(E7)),"",MAX(E7+INDEX(CONFIGURACIÓN!$H$42:$H$56,MATCH($A7,CONFIGURACIÓN!$B$42:$B$56,0)),-INT(-E7*(1+CONFIGURACIÓN!$C$17)/(INDEX(CONFIGURACIÓN!$H$42:$H$56,MATCH($A7,CONFIGURACIÓN!$B$42:$B$56,0))))*(INDEX(CONFIGURACIÓN!$H$42:$H$56,MATCH($A7,CONFIGURACIÓN!$B$42:$B$56,0)))))) | V7: =IF($A7="","",IF(U7="","",IF(NOT(ISNUMBER(E7)),"sin carga inicial registrada",IF(U7>E7,"OK","ERROR: debe ser > "&E7)))) | W7: Ciclo 1 abierto al crear el sistema (27/09/2026). Primera sesión = calibración.
A8: Remo bajo en polea | B8: 1 | C8: ACTIVO | D8: =IF($A8="","",IF(_xlfn.MINIFS(HISTORIAL!$A$5:$A$2004,HISTORIAL!$E$5:$E$2004,$A8,HISTORIAL!$F$5:$F$2004,"Bilbo",HISTORIAL!$G$5:$G$2004,$B8)=0,"",INDEX(HISTORIAL!$B$5:$B$2004,_xlfn.MINIFS(HISTORIAL!$A$5:$A$2004,HISTORIAL!$E$5:$E$2004,$A8,HISTORIAL!$F$5:$F$2004,"Bilbo",HISTORIAL!$G$5:$G$2004,$B8)))) | E8: =IF($A8="","",IF(_xlfn.MINIFS(HISTORIAL!$A$5:$A$2004,HISTORIAL!$E$5:$E$2004,$A8,HISTORIAL!$F$5:$F$2004,"Bilbo",HISTORIAL!$G$5:$G$2004,$B8)=0,"",INDEX(HISTORIAL!$J$5:$J$2004,_xlfn.MINIFS(HISTORIAL!$A$5:$A$2004,HISTORIAL!$E$5:$E$2004,$A8,HISTORIAL!$F$5:$F$2004,"Bilbo",HISTORIAL!$G$5:$G$2004,$B8)))) | F8: =IF($A8="","",IF(_xlfn.MINIFS(HISTORIAL!$A$5:$A$2004,HISTORIAL!$E$5:$E$2004,$A8,HISTORIAL!$F$5:$F$2004,"Bilbo",HISTORIAL!$G$5:$G$2004,$B8)=0,"",INDEX(HISTORIAL!$K$5:$K$2004,_xlfn.MINIFS(HISTORIAL!$A$5:$A$2004,HISTORIAL!$E$5:$E$2004,$A8,HISTORIAL!$F$5:$F$2004,"Bilbo",HISTORIAL!$G$5:$G$2004,$B8)))) | G8: =IF($A8="","",IF(_xlfn.MAXIFS(HISTORIAL!$A$5:$A$2004,HISTORIAL!$E$5:$E$2004,$A8,HISTORIAL!$F$5:$F$2004,"Bilbo",HISTORIAL!$G$5:$G$2004,$B8)=0,"",INDEX(HISTORIAL!$B$5:$B$2004,_xlfn.MAXIFS(HISTORIAL!$A$5:$A$2004,HISTORIAL!$E$5:$E$2004,$A8,HISTORIAL!$F$5:$F$2004,"Bilbo",HISTORIAL!$G$5:$G$2004,$B8)))) | H8: =IF($A8="","",IF(_xlfn.MAXIFS(HISTORIAL!$A$5:$A$2004,HISTORIAL!$E$5:$E$2004,$A8,HISTORIAL!$F$5:$F$2004,"Bilbo",HISTORIAL!$G$5:$G$2004,$B8)=0,"",INDEX(HISTORIAL!$J$5:$J$2004,_xlfn.MAXIFS(HISTORIAL!$A$5:$A$2004,HISTORIAL!$E$5:$E$2004,$A8,HISTORIAL!$F$5:$F$2004,"Bilbo",HISTORIAL!$G$5:$G$2004,$B8)))) | I8: =IF($A8="","",IF(_xlfn.MAXIFS(HISTORIAL!$A$5:$A$2004,HISTORIAL!$E$5:$E$2004,$A8,HISTORIAL!$F$5:$F$2004,"Bilbo",HISTORIAL!$G$5:$G$2004,$B8)=0,"",INDEX(HISTORIAL!$K$5:$K$2004,_xlfn.MAXIFS(HISTORIAL!$A$5:$A$2004,HISTORIAL!$E$5:$E$2004,$A8,HISTORIAL!$F$5:$F$2004,"Bilbo",HISTORIAL!$G$5:$G$2004,$B8)))) | J8: =IF($A8="","",COUNTIFS(HISTORIAL!$E$5:$E$2004,$A8,HISTORIAL!$F$5:$F$2004,"Bilbo",HISTORIAL!$G$5:$G$2004,$B8)) -> 0 | K8: =IF($A8="","",IF(J8=0,"",_xlfn.MAXIFS(HISTORIAL!$J$5:$J$2004,HISTORIAL!$E$5:$E$2004,$A8,HISTORIAL!$F$5:$F$2004,"Bilbo",HISTORIAL!$G$5:$G$2004,$B8))) | L8: =IF($A8="","",IF(J8=0,"",_xlfn.MAXIFS(HISTORIAL!$K$5:$K$2004,HISTORIAL!$E$5:$E$2004,$A8,HISTORIAL!$F$5:$F$2004,"Bilbo",HISTORIAL!$G$5:$G$2004,$B8,HISTORIAL!$J$5:$J$2004,K8))) | M8: =IF($A8="","",IF(J8=0,"",_xlfn.MAXIFS(HISTORIAL!$T$5:$T$2004,HISTORIAL!$E$5:$E$2004,$A8,HISTORIAL!$F$5:$F$2004,"Bilbo",HISTORIAL!$G$5:$G$2004,$B8))) | N8: =IF($A8="","",IF(J8=0,"",H8-E8)) | O8: =IF($A8="","",IF(COUNTIFS($A$6:$A$105,$A8,$B$6:$B$105,$B8-1)=0,"",SUMIFS($E$6:$E$105,$A$6:$A$105,$A8,$B$6:$B$105,$B8-1))) | P8: =IF($A8="","",IF(OR(O8="",NOT(ISNUMBER(E8))),"—",IF(E8>O8,"OK","ERROR: debe ser > "&O8))) -> — | Q8: =IF($A8="","",IF(OR(O8="",NOT(ISNUMBER(E8))),"",IF(_xlfn.MAXIFS(HISTORIAL!$K$5:$K$2004,HISTORIAL!$E$5:$E$2004,$A8,HISTORIAL!$F$5:$F$2004,"Bilbo",HISTORIAL!$G$5:$G$2004,$B8-1,HISTORIAL!$J$5:$J$2004,E8)=0,"sin dato comparable",_xlfn.MAXIFS(HISTORIAL!$K$5:$K$2004,HISTORIAL!$E$5:$E$2004,$A8,HISTORIAL!$F$5:$F$2004,"Bilbo",HISTORIAL!$G$5:$G$2004,$B8-1,HISTORIAL!$J$5:$J$2004,E8)))) | R8: =IF($A8="","",IF(AND(ISNUMBER(Q8),ISNUMBER(F8)),F8-Q8,"")) | S8: =IF($A8="","",SUMIFS(HISTORIAL!$R$5:$R$2004,HISTORIAL!$E$5:$E$2004,$A8,HISTORIAL!$F$5:$F$2004,"Bilbo",HISTORIAL!$G$5:$G$2004,$B8)+SUMIFS(HISTORIAL!$R$5:$R$2004,HISTORIAL!$E$5:$E$2004,$A8,HISTORIAL!$F$5:$F$2004,"Post-Bilbo",HISTORIAL!$G$5:$G$2004,$B8)) -> 0 | T8: =IF($A8="","",IF(NOT(ISNUMBER(E8)),"",MAX(E8+INDEX(CONFIGURACIÓN!$H$42:$H$56,MATCH($A8,CONFIGURACIÓN!$B$42:$B$56,0)),-INT(-E8*(1+CONFIGURACIÓN!$C$17)/(INDEX(CONFIGURACIÓN!$H$42:$H$56,MATCH($A8,CONFIGURACIÓN!$B$42:$B$56,0))))*(INDEX(CONFIGURACIÓN!$H$42:$H$56,MATCH($A8,CONFIGURACIÓN!$B$42:$B$56,0)))))) | V8: =IF($A8="","",IF(U8="","",IF(NOT(ISNUMBER(E8)),"sin carga inicial registrada",IF(U8>E8,"OK","ERROR: debe ser > "&E8)))) | W8: Ciclo 1 abierto al crear el sistema (27/09/2026). Primera sesión = calibración.
